Workbook
Name UPDATE: 'Data Sheet'!$E$1

Sheet Profit & Loss
A1: ='Data Sheet'!B1 -> HINDUSTAN UNILEVER LTD | H1: =UPDATE | M1: SCREENER.IN
A3: Narration | B3: ='Data Sheet'!B16 -> 42825 | C3: ='Data Sheet'!C16 -> 43190 | D3: ='Data Sheet'!D16 -> 43555 | E3: ='Data Sheet'!E16 -> 43921 | F3: ='Data Sheet'!F16 -> 44286 | G3: ='Data Sheet'!G16 -> 44651 | H3: ='Data Sheet'!H16 -> 45016 | I3: ='Data Sheet'!I16 -> 45382 | ... K3: ='Data Sheet'!K16 -> 46112 | L3: Trailing | M3: Best Case | N3: Worst Case
A4: Sales | B4: ='Data Sheet'!B17 -> 33162 | C4: ='Data Sheet'!C17 -> 35545 | D4: ='Data Sheet'!D17 -> 39310 | E4: ='Data Sheet'!E17 -> 39783 | F4: ='Data Sheet'!F17 -> 47028 | G4: ='Data Sheet'!G17 -> 52446 | H4: ='Data Sheet'!H17 -> 60580 | I4: ='Data Sheet'!I17 -> 61896 | ... K4: ='Data Sheet'!K17 -> 64468 | L4: =SUM(Quarters!H4:K4) -> 65225 | M4: =$K4+M23*K4 -> 65843.745 | N4: =$K4+N23*L4 -> 65834.541
A5: Expenses | B5: =SUM('Data Sheet'!B18,'Data Sheet'!B20:B24,-1*'Data Sheet'!B19) -> 26834 | C5: =SUM('Data Sheet'!C18,'Data Sheet'!C20:C24,-1*'Data Sheet'!C19) -> 28046 | D5: =SUM('Data Sheet'!D18,'Data Sheet'!D20:D24,-1*'Data Sheet'!D19) -> 30430 | E5: =SUM('Data Sheet'!E18,'Data Sheet'!E20:E24,-1*'Data Sheet'!E19) -> 29922 | F5: =SUM('Data Sheet'!F18,'Data Sheet'!F20:F24,-1*'Data Sheet'!F19) -> 35402 | G5: =SUM('Data Sheet'!G18,'Data Sheet'!G20:G24,-1*'Data Sheet'!G19) -> 39589 | H5: =SUM('Data Sheet'!H18,'Data Sheet'!H20:H24,-1*'Data Sheet'!H19) -> 46433 | I5: =SUM('Data Sheet'!I18,'Data Sheet'!I20:I24,-1*'Data Sheet'!I19) -> 47237 | ... K5: =SUM('Data Sheet'!K18,'Data Sheet'!K20:K24,-1*'Data Sheet'!K19) -> 49429 | L5: =SUM(Quarters!H5:K5) -> 50108 | M5: =M4-M6 -> 50366.286 | N5: =N4-N6 -> 50576.269
A6: Operating Profit | B6: =B4-B5 -> 6328 | C6: =C4-C5 -> 7499 | D6: =D4-D5 -> 8880 | E6: =E4-E5 -> 9861 | F6: =F4-F5 -> 11626 | G6: =G4-G5 -> 12857 | H6: =H4-H5 -> 14147 | I6: =I4-I5 -> 14659 | ... K6: =K4-K5 -> 15039 | L6: =SUM(Quarters!H6:K6) -> 15117 | M6: =M4*M24 -> 15477.459 | N6: =N4*N24 -> 15258.271
A7: Other Income | B7: ='Data Sheet'!B25 -> 606 | C7: ='Data Sheet'!C25 -> 353 | D7: ='Data Sheet'!D25 -> 322 | E7: ='Data Sheet'!E25 -> 424 | F7: ='Data Sheet'!F25 -> 170 | G7: ='Data Sheet'!G25 -> 219 | H7: ='Data Sheet'!H25 -> 448 | I7: ='Data Sheet'!I25 -> 817 | ... K7: ='Data Sheet'!K25 -> 4923 | L7: =SUM(Quarters!H7:K7) -> 4894 | M7: 0 | N7: 0
A8: Depreciation | B8: ='Data Sheet'!B26 -> 432 | C8: ='Data Sheet'!C26 -> 520 | D8: ='Data Sheet'!D26 -> 565 | E8: ='Data Sheet'!E26 -> 1002 | F8: ='Data Sheet'!F26 -> 1074 | G8: ='Data Sheet'!G26 -> 1091 | H8: ='Data Sheet'!H26 -> 1137 | I8: ='Data Sheet'!I26 -> 1216 | ... K8: ='Data Sheet'!K26 -> 1333 | L8: =SUM(Quarters!H8:K8) -> 1368 | M8: =+$L8 -> 1368 | N8: =+$L8 -> 1368
A9: Interest | B9: ='Data Sheet'!B27 -> 35 | C9: ='Data Sheet'!C27 -> 26 | D9: ='Data Sheet'!D27 -> 33 | E9: ='Data Sheet'!E27 -> 118 | F9: ='Data Sheet'!F27 -> 117 | G9: ='Data Sheet'!G27 -> 106 | H9: ='Data Sheet'!H27 -> 114 | I9: ='Data Sheet'!I27 -> 334 | ... K9: ='Data Sheet'!K27 -> 410 | L9: =SUM(Quarters!H9:K9) -> 415 | M9: =+$L9 -> 415 | N9: =+$L9 -> 415
A10: Profit before tax | B10: ='Data Sheet'!B28 -> 6467 | C10: ='Data Sheet'!C28 -> 7306 | D10: ='Data Sheet'!D28 -> 8604 | E10: ='Data Sheet'!E28 -> 9165 | F10: ='Data Sheet'!F28 -> 10605 | G10: ='Data Sheet'!G28 -> 11879 | H10: ='Data Sheet'!H28 -> 13344 | I10: ='Data Sheet'!I28 -> 13926 | ... K10: ='Data Sheet'!K28 -> 18219 | L10: =SUM(Quarters!H10:K10) -> 18228 | M10: =M6+M7-SUM(M8:M9) -> 13694.459 | N10: =N6+N7-SUM(N8:N9) -> 13475.271
A11: Tax | B11: ='Data Sheet'!B29 -> 1977 | C11: ='Data Sheet'!C29 -> 2079 | D11: ='Data Sheet'!D29 -> 2544 | E11: ='Data Sheet'!E29 -> 2409 | F11: ='Data Sheet'!F29 -> 2606 | G11: ='Data Sheet'!G29 -> 2987 | H11: ='Data Sheet'!H29 -> 3201 | I11: ='Data Sheet'!I29 -> 3644 | ... K11: ='Data Sheet'!K29 -> 3160 | L11: =SUM(Quarters!H11:K11) -> 3169 | M11: =IF($L10>0,$L11/$L10,0) -> 0.17385341 | N11: =IF($L10>0,$L11/$L10,0) -> 0.17385341
A12: Net profit | B12: ='Data Sheet'!B30 -> 4476 | C12: ='Data Sheet'!C30 -> 5214 | D12: ='Data Sheet'!D30 -> 6054 | E12: ='Data Sheet'!E30 -> 6748 | F12: ='Data Sheet'!F30 -> 7995 | G12: ='Data Sheet'!G30 -> 8879 | H12: ='Data Sheet'!H30 -> 10120 | I12: ='Data Sheet'!I30 -> 10277 | ... K12: ='Data Sheet'!K30 -> 15040 | L12: =SUM(Quarters!H12:K12) -> 15040 | M12: =M10-M11*M10 -> 11313.63 | N12: =N10-N11*N10 -> 11132.55
A13: EPS | B13: =IF('Data Sheet'!B93>0,B12/'Data Sheet'!B93,0) -> 20.681052 | C13: =IF('Data Sheet'!C93>0,C12/'Data Sheet'!C93,0) -> 24.088704 | D13: =IF('Data Sheet'!D93>0,D12/'Data Sheet'!D93,0) -> 27.966924 | E13: =IF('Data Sheet'!E93>0,E12/'Data Sheet'!E93,0) -> 31.171471 | F13: =IF('Data Sheet'!F93>0,F12/'Data Sheet'!F93,0) -> 34.027068 | G13: =IF('Data Sheet'!G93>0,G12/'Data Sheet'!G93,0) -> 37.789411 | H13: =IF('Data Sheet'!H93>0,H12/'Data Sheet'!H93,0) -> 43.071161 | I13: =IF('Data Sheet'!I93>0,I12/'Data Sheet'!I93,0) -> 43.73936 | ... K13: =IF('Data Sheet'!K93>0,K12/'Data Sheet'!K93,0) -> 64.010895 | L13: =IF('Data Sheet'!$B6>0,'Profit & Loss'!L12/'Data Sheet'!$B6,0) -> 64.011133 | M13: =IF('Data Sheet'!$B6>0,'Profit & Loss'!M12/'Data Sheet'!$B6,0) -> 48.151482 | N13: =IF('Data Sheet'!$B6>0,'Profit & Loss'!N12/'Data Sheet'!$B6,0) -> 47.380792
A14: Price to earning | B14: =IF(B15>0,B15/B13,"") -> 42.193696 | C14: =IF(C15>0,C15/C13,"") -> 52.975453 | D14: =IF(D15>0,D15/D13,"") -> 58.409356 | E14: =IF(E15>0,E15/E13,"") -> 70.571903 | F14: =IF(F15>0,F15/F13,"") -> 68.390258 | G14: =IF(G15>0,G15/G13,"") -> 51.884905 | H14: =IF(H15>0,H15/H13,"") -> 56.892824 | I14: =IF(I15>0,I15/I13,"") -> 49.546678 | ... K14: =IF(K15>0,K15/K13,"") -> 32.107034 | L14: =IF(L13>0,L15/L13,0) -> 35.49695 | M14: =M25 -> 41.212619 | N14: =N25 -> 35.49695
A15: Price | B15: ='Data Sheet'!B90 -> 872.61 | C15: ='Data Sheet'!C90 -> 1276.11 | D15: ='Data Sheet'!D90 -> 1633.53 | E15: ='Data Sheet'!E90 -> 2199.83 | F15: ='Data Sheet'!F90 -> 2327.12 | G15: ='Data Sheet'!G90 -> 1960.7 | H15: ='Data Sheet'!H90 -> 2450.44 | I15: ='Data Sheet'!I90 -> 2167.14 | ... K15: ='Data Sheet'!K90 -> 2055.2 | L15: ='Data Sheet'!B8 -> 2272.2 | M15: =M13*M14 -> 1984.4487 | N15: =N13*N14 -> 1681.8736
A17: RATIOS:
A18: Dividend Payout | B18: =IF('Data Sheet'!B30>0,'Data Sheet'!B31/'Data Sheet'!B30,0) -> 0.82037534 | C18: =IF('Data Sheet'!C30>0,'Data Sheet'!C31/'Data Sheet'!C30,0) -> 0.82853855 | D18: =IF('Data Sheet'!D30>0,'Data Sheet'!D31/'Data Sheet'!D30,0) -> 0.78493558 | E18: =IF('Data Sheet'!E30>0,'Data Sheet'!E31/'Data Sheet'!E30,0) -> 0.80023711 | F18: =IF('Data Sheet'!F30>0,'Data Sheet'!F31/'Data Sheet'!F30,0) -> 1.1904315 | G18: =IF('Data Sheet'!G30>0,'Data Sheet'!G31/'Data Sheet'!G30,0) -> 0.89987611 | H18: =IF('Data Sheet'!H30>0,'Data Sheet'!H31/'Data Sheet'!H30,0) -> 0.90563241 | I18: =IF('Data Sheet'!I30>0,'Data Sheet'!I31/'Data Sheet'!I30,0) -> 0.960397 | ... K18: =IF('Data Sheet'!K30>0,'Data Sheet'!K31/'Data Sheet'!K30,0) -> 0.640625
A19: OPM | B19: =IF(B6>0,B6/B4,0) -> 0.19082082 | C19: =IF(C6>0,C6/C4,0) -> 0.21097201 | D19: =IF(D6>0,D6/D4,0) -> 0.22589672 | E19: =IF(E6>0,E6/E4,0) -> 0.24786969 | F19: =IF(F6>0,F6/F4,0) -> 0.24721443 | G19: =IF(G6>0,G6/G4,0) -> 0.24514739 | H19: =IF(H6>0,H6/H4,0) -> 0.23352592 | I19: =IF(I6>0,I6/I4,0) -> 0.23683275 | ... L19: =IF(L6>0,L6/L4,0) -> 0.23176696
G22: TRENDS: | H22: 10 YEARS | I22: 7 YEARS | J22: 5 YEARS | K22: 3 YEARS | L22: RECENT | M22: BEST | N22: WORST
G23: Sales Growth | H23: =IF(B4=0,"",POWER($K4/B4,1/9)-1) -> 0.076658974 | I23: =IF(D4=0,"",POWER($K4/D4,1/7)-1) -> 0.073227008 | J23: =IF(F4=0,"",POWER($K4/F4,1/5)-1) -> 0.065117542 | K23: =IF(H4=0,"",POWER($K4/H4,1/3)-1) -> 0.020951182 | L23: =IF(ISERROR(MAX(IF(J4=0,"",(K4-J4)/J4),IF(K4=0,"",(L4-K4)/K4))),"",MAX(IF(J4=0,"",(K4-J4)/J4),IF(K4=0,"",(L4-K4)/K4))) -> 0.021339966 | M23: =MAX(K23:L23) -> 0.021339966 | N23: =MIN(H23:L23) -> 0.020951182
G24: OPM | H24: =IF(SUM(B4:$K$4)=0,"",SUMPRODUCT(B19:$K$19,B4:$K$4)/SUM(B4:$K$4)) -> 0.23271652 | I24: =IF(SUM(E4:$K$4)=0,"",SUMPRODUCT(E19:$K$19,E4:$K$4)/SUM(E4:$K$4)) -> 0.23895901 | J24: =IF(SUM(G4:$K$4)=0,"",SUMPRODUCT(G19:$K$19,G4:$K$4)/SUM(G4:$K$4)) -> 0.2365038 | K24: =IF(SUM(I4:$K$4)=0,"",SUMPRODUCT(I19:$K$19,I4:$K$4)/SUM(I4:$K$4)) -> 0.23506346 | L24: =L19 -> 0.23176696 | M24: =MAX(K24:L24) -> 0.23506346 | N24: =MIN(H24:L24) -> 0.23176696
G25: Price to Earning | H25: =IF(ISERROR(AVERAGEIF(B14:$L14,">0")),"",AVERAGEIF(B14:$L14,">0")) -> 51.469897 | I25: =IF(ISERROR(AVERAGEIF(E14:$L14,">0")),"",AVERAGEIF(E14:$L14,">0")) -> 51.573796 | J25: =IF(ISERROR(AVERAGEIF(G14:$L14,">0")),"",AVERAGEIF(G14:$L14,">0")) -> 45.604701 | K25: =IF(ISERROR(AVERAGEIF(I14:$L14,">0")),"",AVERAGEIF(I14:$L14,">0")) -> 41.212619 | L25: =L14 -> 35.49695 | M25: =MAX(K25:L25) -> 41.212619 | N25: =MIN(H25:L25) -> 35.49695

Sheet DCF
A1: DCF VALUATION - HUL
B2: ='Profit & Loss'!F3 -> 44286 | C2: ='Profit & Loss'!G3 -> 44651 | D2: ='Profit & Loss'!H3 -> 45016 | E2: ='Profit & Loss'!I3 -> 45382 | F2: ='Profit & Loss'!J3 -> 45747 | G2: ='Profit & Loss'!K3 -> 46112 | H2: =DATE(YEAR(G2)+1,MONTH(G2),DAY(G2)) -> 46477 | I2: =DATE(YEAR(H2)+1,MONTH(H2),DAY(H2)) -> 46843 | J2: =DATE(YEAR(I2)+1,MONTH(I2),DAY(I2)) -> 47208 | K2: =DATE(YEAR(J2)+1,MONTH(J2),DAY(J2)) -> 47573 | L2: =DATE(YEAR(K2)+1,MONTH(K2),DAY(K2)) -> 47938 | O2: Revenue
A3: Revenue | B3: ='Profit & Loss'!F4 -> 47028 | C3: ='Profit & Loss'!G4 -> 52446 | D3: ='Profit & Loss'!H4 -> 60580 | E3: ='Profit & Loss'!I4 -> 61896 | F3: ='Profit & Loss'!J4 -> 63121 | G3: ='Profit & Loss'!K4 -> 64468 | H3: =G3*(1+H4) -> 68763.572 | I3: =H3*(1+I4) -> 72677.299 | J3: =I3*(1+J4) -> 75386.729 | K3: =J3*(1+K4) -> 78431.723 | L3: =K3*(1+L4) -> 81922.855 | O3: LATEST
C4: =C3/B3-1 -> 0.11520796 | D4: =D3/C3-1 -> 0.15509286 | E4: =E3/D3-1 -> 0.021723341 | F4: =F3/E3-1 -> 0.019791263 | G4: =G3/F3-1 -> 0.021339966 | H4: =AVERAGE(C4:G4) -> 0.066631078 | I4: =AVERAGE(D4:H4) -> 0.056915701 | J4: =AVERAGE(E4:I4) -> 0.03728027 | K4: =AVERAGE(F4:J4) -> 0.040391655 | L4: =AVERAGE(G4:K4) -> 0.044511734 | O4: AVERAGE
O5: CAGR
A6: EBIT - Operating Profit | B6: ='Profit & Loss'!F6-'Profit & Loss'!F8 -> 10552 | C6: ='Profit & Loss'!G6-'Profit & Loss'!G8 -> 11766 | D6: ='Profit & Loss'!H6-'Profit & Loss'!H8 -> 13010 | E6: ='Profit & Loss'!I6-'Profit & Loss'!I8 -> 13443 | F6: ='Profit & Loss'!J6-'Profit & Loss'!J8 -> 13488 | G6: ='Profit & Loss'!K6-'Profit & Loss'!K8 -> 13706 | H6: =H3*H7 -> 14978.456 | I6: =I3*I7 -> 15751.607 | J6: =J3*J7 -> 16243.197 | K6: =K3*K7 -> 16908.536 | L6: =L3*L7 -> 17639.263 | O6: BOTTOM UP
B7: =B6/B3 -> 0.22437697 | C7: =C6/C3 -> 0.22434504 | D7: =D6/D3 -> 0.21475735 | E7: =E6/E3 -> 0.21718689 | F7: =F6/F3 -> 0.21368483 | G7: =G6/G3 -> 0.2126016 | H7: =AVERAGE(B7:G7) -> 0.21782545 | I7: =AVERAGE(C7:H7) -> 0.21673353 | J7: =AVERAGE(D7:I7) -> 0.21546494 | K7: =AVERAGE(E7:J7) -> 0.21558287 | L7: =AVERAGE(F7:K7) -> 0.21531554
O8: REGRESSION ANALYSIS
A9: TAX % | B9: 0.24 | C9: 0.24 | D9: 0.24 | E9: 0.24 | F9: 0.24 | G9: ='Profit & Loss'!K11/'Profit & Loss'!K10 -> 0.1734453 | H9: 0.24 | I9: 0.24 | J9: 0.24 | K9: 0.24 | L9: 0.24
A11: EBIT*(1-t) | B11: =B6*(1-B9) -> 8019.52 | C11: =C6*(1-C9) -> 8942.16 | D11: =D6*(1-D9) -> 9887.6 | E11: =E6*(1-E9) -> 10216.68 | F11: =F6*(1-F9) -> 10250.88 | G11: =G6*(1-G9) -> 11328.759 | H11: =H6*(1-H9) -> 11383.626 | I11: =I6*(1-I9) -> 11971.222 | ... L11: =L6*(1-L9) -> 13405.84
A13: Depreciation | B13: ='Profit & Loss'!F8 -> 1074 | C13: ='Profit & Loss'!G8 -> 1091 | D13: ='Profit & Loss'!H8 -> 1137 | E13: ='Profit & Loss'!I8 -> 1216 | F13: ='Profit & Loss'!J8 -> 1355 | G13: ='Profit & Loss'!K8 -> 1333 | H13: =AVERAGE(B13:G13) -> 1201 | I13: =AVERAGE(C13:H13) -> 1222.1667 | J13: =AVERAGE(D13:I13) -> 1244.0278 | K13: =AVERAGE(E13:J13) -> 1261.8657 | L13: =AVERAGE(F13:K13) -> 1269.51
A15: Capex | C15: =-('Balance Sheet'!G10+'Balance Sheet'!G11-'Balance Sheet'!F10-'Balance Sheet'!F11) -> -598 | D15: =-('Balance Sheet'!H10+'Balance Sheet'!H11-'Balance Sheet'!G10-'Balance Sheet'!G11) -> -1024 | E15: =-('Balance Sheet'!I10+'Balance Sheet'!I11-'Balance Sheet'!H10-'Balance Sheet'!H11) -> -959 | F15: =-('Balance Sheet'!J10+'Balance Sheet'!J11-'Balance Sheet'!I10-'Balance Sheet'!I11) -> -575 | G15: =-('Balance Sheet'!K10+'Balance Sheet'!K11-'Balance Sheet'!J10-'Balance Sheet'!J11) -> -2964 | H15: =H3*H16 -> -1359.937 | I15: =I3*I16 -> -1559.0703 | J15: =J3*J16 -> -1685.775 | K15: =K3*K16 -> -1861.5995 | L15: =L3*L16 -> -2184.0999
A16: % OF REVENUE | C16: =C15/C3 -> -0.011402204 | D16: =D15/D3 -> -0.016903268 | E16: =E15/E3 -> -0.015493731 | F16: =F15/F3 -> -0.0091094881 | G16: =G15/G3 -> -0.045976298 | H16: =AVERAGE(C16:G16) -> -0.019776998 | I16: =AVERAGE(D16:H16) -> -0.021451957 | J16: =AVERAGE(E16:I16) -> -0.022361695 | K16: =AVERAGE(F16:J16) -> -0.023735287 | L16: =AVERAGE(G16:K16) -> -0.026660447
A19: Working capital | C19: =-('Balance Sheet'!G16-'Balance Sheet'!F16) -> -1020 | D19: =-('Balance Sheet'!H16-'Balance Sheet'!G16) -> -1034 | E19: =-('Balance Sheet'!I16-'Balance Sheet'!H16) -> 1523 | F19: =-('Balance Sheet'!J16-'Balance Sheet'!I16) -> 1412 | G19: =-('Balance Sheet'!K16-'Balance Sheet'!J16) -> 4346 | H19: =H3*H20 -> 1070.95 | I19: =I3*I20 -> 1640.9786 | J19: =J3*J20 -> 2299.931 | K19: =K3*K20 -> 2485.4199 | L19: =L3*L20 -> 2748.7418
A20: % OF REVENUE | C20: =C19/C3 -> -0.019448576 | D20: =D19/D3 -> -0.017068339 | E20: =E19/E3 -> 0.02460579 | F20: =F19/F3 -> 0.022369734 | G20: =G19/G3 -> 0.06741329 | H20: =AVERAGE(C20:G20) -> 0.01557438 | I20: =AVERAGE(D20:H20) -> 0.022578971 | J20: =AVERAGE(E20:I20) -> 0.030508433 | K20: =AVERAGE(F20:J20) -> 0.031688962 | L20: =AVERAGE(G20:K20) -> 0.033552807
A23: FREE CASH FLOW TO THE FIRM | B23: =SUM(B11:B19) -> 9093.52 | C23: =SUM(C11:C15,C19) -> 8415.16 | D23: =SUM(D11:D15,D19) -> 8966.6 | E23: =SUM(E11:E15,E19) -> 11996.68 | F23: =SUM(F11:F15,F19) -> 12442.88 | G23: =SUM(G11:G15,G19) -> 14043.759 | H23: =SUM(H11:H15,H19) -> 12295.639 | I23: =SUM(I11:I15,I19) -> 13275.297 | J23: =SUM(J11:J15,J19) -> 14203.013 | ... L23: =SUM(L11:L15,L19) -> 15239.992
A25: terminal value | L25: =B34 -> 232954.16
B26: =B23+L25 -> 242047.68 | C26: =C23+M25 -> 8415.16 | D26: =D23+N25 -> 8966.6 | E26: =E23+O25 -> 11996.68 | F26: =F23+P25 -> 12442.88 | G26: =G23+Q25 -> 14043.759 | H26: =H23+R25 -> 12295.639 | I26: =I23+S25 -> 13275.297 | ... L26: =L23+V25 -> 15239.992
A28: calculation of terminal value
A29: annual cash flow | B29: =L23 -> 15239.992 | D29: Annual CF | G29: WACC | J29: WAIGHT AGE
A30: Growth rate | B30: 0.07 | C30: 0.065 | D30: 0.06 | E30: 0.055 | F30: 0.05 | G30: Cost of debt | H30: ='Profit & Loss'!K9/AVERAGE('Balance Sheet'!K6) -> 0.27740189 | I30: =H30*(1-30%) -> 0.19418133 | J30: =L30/L32 -> 0.029432264 | L30: ='Balance Sheet'!K6 -> 1478
B31: =B29*(1+B30) -> 16306.792 | G31: Cost of equity | H31: CPAM | I31: Rf+beta*(Rm-Rf) | J31: =L31/L32 -> 0.97056774 | L31: ='Balance Sheet'!K4+'Balance Sheet'!K5 -> 48739
H32: RF | I32: 7.07 | L32: =SUM(L30:L31) -> 50217
A33: Discount rate - Growth rate | B33: 0.07 | C33: 0.065 | D33: 0.06 | E33: 0.055 | F33: 0.05 | H33: BETA | I33: 0.62
A34: Terminal value | B34: =B31/B33 -> 232954.16 | H34: MARKET RETURN | I34: 0.13
I35: =I32+I33*(I34-I32) -> 2.7672
A36: calcuation of intrinsic value
A37: Enterprise value | B37: =NPV(I37,G26:L26) -> 3667.0086 | I37: =I30*J30+(I35+J31) -> 3.7434829
A38: Net debt | B38: ='Balance Sheet'!K6-'Data Sheet'!K69 -> -1770
A39: Equity value | B39: =B37-B40 -> 3432.0486
A40: no of shares | B40: ='Data Sheet'!K93 -> 234.96
A41: intrinsic value | B41: =B39/B40 -> 14.606948
A43: current price | B43: 2055
A44: decision | B44: Sell
A47: Minor Professional Improvements Added
A48: Revenue growth stabilized gradually for mature FMCG assumptions.
A49: Tax rate normalized to 24% for realistic forecasting.
A50: DCF structure retained while improving forecast consistency.

Sheet Quarters
A1: ='Profit & Loss'!A1 -> HINDUSTAN UNILEVER LTD | E1: =UPDATE | J1: SCREENER.IN
A3: Narration | B3: ='Data Sheet'!B41 -> 45291 | C3: ='Data Sheet'!C41 -> 45382 | D3: ='Data Sheet'!D41 -> 45473 | E3: ='Data Sheet'!E41 -> 45565 | F3: ='Data Sheet'!F41 -> 45657 | G3: ='Data Sheet'!G41 -> 45747 | H3: ='Data Sheet'!H41 -> 45838 | I3: ='Data Sheet'!I41 -> 45930 | ... K3: ='Data Sheet'!K41 -> 46112
A4: Sales | B4: ='Data Sheet'!B42 -> 15567 | C4: ='Data Sheet'!C42 -> 15210 | D4: ='Data Sheet'!D42 -> 15707 | E4: ='Data Sheet'!E42 -> 15926 | F4: ='Data Sheet'!F42 -> 15556 | G4: ='Data Sheet'!G42 -> 15190 | H4: ='Data Sheet'!H42 -> 16514 | I4: ='Data Sheet'!I42 -> 15919 | ... K4: ='Data Sheet'!K42 -> 16351
A5: Expenses | B5: ='Data Sheet'!B43 -> 11902 | C5: ='Data Sheet'!C43 -> 11675 | D5: ='Data Sheet'!D43 -> 11965 | E5: ='Data Sheet'!E43 -> 12139 | F5: ='Data Sheet'!F43 -> 11867 | G5: ='Data Sheet'!G43 -> 11572 | H5: ='Data Sheet'!H43 -> 12797 | I5: ='Data Sheet'!I43 -> 12137 | ... K5: ='Data Sheet'!K43 -> 12514
A6: Operating Profit | B6: ='Data Sheet'!B50 -> 3665 | C6: ='Data Sheet'!C50 -> 3535 | D6: ='Data Sheet'!D50 -> 3742 | E6: ='Data Sheet'!E50 -> 3787 | F6: ='Data Sheet'!F50 -> 3689 | G6: ='Data Sheet'!G50 -> 3618 | H6: ='Data Sheet'!H50 -> 3717 | I6: ='Data Sheet'!I50 -> 3782 | ... K6: ='Data Sheet'!K50 -> 3837
A7: Other Income | B7: ='Data Sheet'!B44 -> 184 | C7: ='Data Sheet'!C44 -> 309 | D7: ='Data Sheet'!D44 -> 209 | E7: ='Data Sheet'!E44 -> 203 | F7: ='Data Sheet'!F44 -> 733 | G7: ='Data Sheet'!G44 -> 149 | H7: ='Data Sheet'!H44 -> 74 | I7: ='Data Sheet'!I44 -> 269 | ... K7: ='Data Sheet'!K44 -> 503
A8: Depreciation | B8: ='Data Sheet'!B45 -> 313 | C8: ='Data Sheet'!C45 -> 320 | D8: ='Data Sheet'!D45 -> 329 | E8: ='Data Sheet'!E45 -> 338 | F8: ='Data Sheet'!F45 -> 318 | G8: ='Data Sheet'!G45 -> 318 | H8: ='Data Sheet'!H45 -> 361 | I8: ='Data Sheet'!I45 -> 322 | ... K8: ='Data Sheet'!K45 -> 348
A9: Interest | B9: ='Data Sheet'!B46 -> 91 | C9: ='Data Sheet'!C46 -> 105 | D9: ='Data Sheet'!D46 -> 93 | E9: ='Data Sheet'!E46 -> 110 | F9: ='Data Sheet'!F46 -> 109 | G9: ='Data Sheet'!G46 -> 77 | H9: ='Data Sheet'!H46 -> 127 | I9: ='Data Sheet'!I46 -> 124 | ... K9: ='Data Sheet'!K46 -> 76
A10: Profit before tax | B10: ='Data Sheet'!B47 -> 3445 | C10: ='Data Sheet'!C47 -> 3419 | D10: ='Data Sheet'!D47 -> 3529 | E10: ='Data Sheet'!E47 -> 3542 | F10: ='Data Sheet'!F47 -> 3995 | G10: ='Data Sheet'!G47 -> 3372 | H10: ='Data Sheet'!H47 -> 3303 | I10: ='Data Sheet'!I47 -> 3605 | ... K10: ='Data Sheet'!K47 -> 3916
A11: Tax | B11: ='Data Sheet'!B48 -> 937 | C11: ='Data Sheet'!C48 -> 858 | D11: ='Data Sheet'!D48 -> 917 | E11: ='Data Sheet'!E48 -> 947 | F11: ='Data Sheet'!F48 -> 1006 | G11: ='Data Sheet'!G48 -> 897 | H11: ='Data Sheet'!H48 -> 535 | I11: ='Data Sheet'!I48 -> 911 | ... K11: ='Data Sheet'!K48 -> 922
A12: Net profit | B12: ='Data Sheet'!B49 -> 2509 | C12: ='Data Sheet'!C49 -> 2558 | D12: ='Data Sheet'!D49 -> 2610 | E12: ='Data Sheet'!E49 -> 2591 | F12: ='Data Sheet'!F49 -> 2984 | G12: ='Data Sheet'!G49 -> 2464 | H12: ='Data Sheet'!H49 -> 2756 | I12: ='Data Sheet'!I49 -> 2685 | ... K12: ='Data Sheet'!K49 -> 2992
A14: OPM | B14: =IF(B4>0,B6/B4,"") -> 0.23543393 | C14: =IF(C4>0,C6/C4,"") -> 0.23241289 | D14: =IF(D4>0,D6/D4,"") -> 0.23823773 | E14: =IF(E4>0,E6/E4,"") -> 0.23778727 | F14: =IF(F4>0,F6/F4,"") -> 0.23714322 | G14: =IF(G4>0,G6/G4,"") -> 0.23818302 | H14: =IF(H4>0,H6/H4,"") -> 0.22508175 | I14: =IF(I4>0,I6/I4,"") -> 0.23757774 | ... K14: =IF(K4>0,K6/K4,"") -> 0.23466455

Sheet Balance Sheet
A1: ='Profit & Loss'!A1 -> HINDUSTAN UNILEVER LTD | E1: =UPDATE | J1: SCREENER.IN
A3: Narration | B3: ='Data Sheet'!B56 -> 42825 | C3: ='Data Sheet'!C56 -> 43190 | D3: ='Data Sheet'!D56 -> 43555 | E3: ='Data Sheet'!E56 -> 43921 | F3: ='Data Sheet'!F56 -> 44286 | G3: ='Data Sheet'!G56 -> 44651 | H3: ='Data Sheet'!H56 -> 45016 | I3: ='Data Sheet'!I56 -> 45382 | ... K3: ='Data Sheet'!K56 -> 46112
A4: Equity Share Capital | B4: ='Data Sheet'!B57 -> 216 | C4: ='Data Sheet'!C57 -> 216 | D4: ='Data Sheet'!D57 -> 216 | E4: ='Data Sheet'!E57 -> 216 | F4: ='Data Sheet'!F57 -> 235 | G4: ='Data Sheet'!G57 -> 235 | H4: ='Data Sheet'!H57 -> 235 | I4: ='Data Sheet'!I57 -> 235 | ... K4: ='Data Sheet'!K57 -> 235
A5: Reserves | B5: ='Data Sheet'!B58 -> 6528 | C5: ='Data Sheet'!C58 -> 7065 | D5: ='Data Sheet'!D58 -> 7651 | E5: ='Data Sheet'!E58 -> 8013 | F5: ='Data Sheet'!F58 -> 47439 | G5: ='Data Sheet'!G58 -> 48826 | H5: ='Data Sheet'!H58 -> 50069 | I5: ='Data Sheet'!I58 -> 50983 | ... K5: ='Data Sheet'!K58 -> 48504
A6: Borrowings | B6: ='Data Sheet'!B59 -> 277 | C6: ='Data Sheet'!C59 -> 0 | D6: ='Data Sheet'!D59 -> 99 | E6: ='Data Sheet'!E59 -> 0 | F6: ='Data Sheet'!F59 -> 0 | G6: ='Data Sheet'!G59 -> 1043 | H6: ='Data Sheet'!H59 -> 1219 | I6: ='Data Sheet'!I59 -> 1484 | ... K6: ='Data Sheet'!K59 -> 1478
A7: Other Liabilities | B7: ='Data Sheet'!B60 -> 8685 | C7: ='Data Sheet'!C60 -> 10581 | D7: ='Data Sheet'!D60 -> 10663 | E7: ='Data Sheet'!E60 -> 11924 | F7: ='Data Sheet'!F60 -> 21066 | G7: ='Data Sheet'!G60 -> 20402 | H7: ='Data Sheet'!H60 -> 21554 | I7: ='Data Sheet'!I60 -> 25787 | ... K7: ='Data Sheet'!K60 -> 29535
A8: Total | B8: ='Data Sheet'!B61 -> 15706 | C8: ='Data Sheet'!C61 -> 17862 | D8: ='Data Sheet'!D61 -> 18629 | E8: ='Data Sheet'!E61 -> 20153 | F8: ='Data Sheet'!F61 -> 68740 | G8: ='Data Sheet'!G61 -> 70506 | H8: ='Data Sheet'!H61 -> 73077 | I8: ='Data Sheet'!I61 -> 78489 | ... K8: ='Data Sheet'!K61 -> 79752
A10: Net Block | B10: ='Data Sheet'!B62 -> 4419 | C10: ='Data Sheet'!C62 -> 4528 | D10: ='Data Sheet'!D62 -> 4715 | E10: ='Data Sheet'!E62 -> 5479 | F10: ='Data Sheet'!F62 -> 51443 | G10: ='Data Sheet'!G62 -> 51473 | H10: ='Data Sheet'!H62 -> 52678 | I10: ='Data Sheet'!I62 -> 53744 | ... K10: ='Data Sheet'!K62 -> 57428
A11: Capital Work in Progress | B11: ='Data Sheet'!B63 -> 229 | C11: ='Data Sheet'!C63 -> 461 | D11: ='Data Sheet'!D63 -> 406 | E11: ='Data Sheet'!E63 -> 597 | F11: ='Data Sheet'!F63 -> 745 | G11: ='Data Sheet'!G63 -> 1313 | H11: ='Data Sheet'!H63 -> 1132 | I11: ='Data Sheet'!I63 -> 1025 | ... K11: ='Data Sheet'!K63 -> 880
A12: Investments | B12: ='Data Sheet'!B64 -> 3794 | C12: ='Data Sheet'!C64 -> 2873 | D12: ='Data Sheet'!D64 -> 2716 | E12: ='Data Sheet'!E64 -> 1255 | F12: ='Data Sheet'!F64 -> 2709 | G12: ='Data Sheet'!G64 -> 3521 | H12: ='Data Sheet'!H64 -> 2882 | I12: ='Data Sheet'!I64 -> 4625 | ... K12: ='Data Sheet'!K64 -> 4359
A13: Other Assets | B13: ='Data Sheet'!B65 -> 7264 | C13: ='Data Sheet'!C65 -> 10000 | D13: ='Data Sheet'!D65 -> 10792 | E13: ='Data Sheet'!E65 -> 12822 | F13: ='Data Sheet'!F65 -> 13843 | G13: ='Data Sheet'!G65 -> 14199 | H13: ='Data Sheet'!H65 -> 16385 | I13: ='Data Sheet'!I65 -> 19095 | ... K13: ='Data Sheet'!K65 -> 17085
A14: Total | B14: ='Data Sheet'!B66 -> 15706 | C14: ='Data Sheet'!C66 -> 17862 | D14: ='Data Sheet'!D66 -> 18629 | E14: ='Data Sheet'!E66 -> 20153 | F14: ='Data Sheet'!F66 -> 68740 | G14: ='Data Sheet'!G66 -> 70506 | H14: ='Data Sheet'!H66 -> 73077 | I14: ='Data Sheet'!I66 -> 78489 | ... K14: ='Data Sheet'!K66 -> 79752
A16: Working Capital | B16: =B13-B7 -> -1421 | C16: =C13-C7 -> -581 | D16: =D13-D7 -> 129 | E16: =E13-E7 -> 898 | F16: =F13-F7 -> -7223 | G16: =G13-G7 -> -6203 | H16: =H13-H7 -> -5169 | I16: =I13-I7 -> -6692 | ... K16: =K13-K7 -> -12450
A17: Debtors | B17: ='Data Sheet'!B67 -> 1085 | C17: ='Data Sheet'!C67 -> 1310 | D17: ='Data Sheet'!D67 -> 1816 | E17: ='Data Sheet'!E67 -> 1149 | F17: ='Data Sheet'!F67 -> 1758 | G17: ='Data Sheet'!G67 -> 2236 | H17: ='Data Sheet'!H67 -> 3079 | I17: ='Data Sheet'!I67 -> 2997 | ... K17: ='Data Sheet'!K67 -> 3379
A18: Inventory | B18: ='Data Sheet'!B68 -> 2541 | C18: ='Data Sheet'!C68 -> 2513 | D18: ='Data Sheet'!D68 -> 2574 | E18: ='Data Sheet'!E68 -> 2767 | F18: ='Data Sheet'!F68 -> 3579 | G18: ='Data Sheet'!G68 -> 4096 | H18: ='Data Sheet'!H68 -> 4251 | I18: ='Data Sheet'!I68 -> 4022 | ... K18: ='Data Sheet'!K68 -> 4789
A20: Debtor Days | B20: =IF('Profit & Loss'!B4>0,'Balance Sheet'!B17/('Profit & Loss'!B4/365),0) -> 11.942133 | C20: =IF('Profit & Loss'!C4>0,'Balance Sheet'!C17/('Profit & Loss'!C4/365),0) -> 13.451962 | D20: =IF('Profit & Loss'!D4>0,'Balance Sheet'!D17/('Profit & Loss'!D4/365),0) -> 16.861867 | E20: =IF('Profit & Loss'!E4>0,'Balance Sheet'!E17/('Profit & Loss'!E4/365),0) -> 10.541814 | F20: =IF('Profit & Loss'!F4>0,'Balance Sheet'!F17/('Profit & Loss'!F4/365),0) -> 13.644425 | G20: =IF('Profit & Loss'!G4>0,'Balance Sheet'!G17/('Profit & Loss'!G4/365),0) -> 15.56153 | H20: =IF('Profit & Loss'!H4>0,'Balance Sheet'!H17/('Profit & Loss'!H4/365),0) -> 18.551255 | I20: =IF('Profit & Loss'!I4>0,'Balance Sheet'!I17/('Profit & Loss'!I4/365),0) -> 17.673275 | ... K20: =IF('Profit & Loss'!K4>0,'Balance Sheet'!K17/('Profit & Loss'!K4/365),0) -> 19.130964
A21: Inventory Turnover | B21: =IF('Balance Sheet'!B18>0,'Profit & Loss'!B4/'Balance Sheet'!B18,0) -> 13.050767 | C21: =IF('Balance Sheet'!C18>0,'Profit & Loss'!C4/'Balance Sheet'!C18,0) -> 14.144449 | D21: =IF('Balance Sheet'!D18>0,'Profit & Loss'!D4/'Balance Sheet'!D18,0) -> 15.27195 | E21: =IF('Balance Sheet'!E18>0,'Profit & Loss'!E4/'Balance Sheet'!E18,0) -> 14.377665 | F21: =IF('Balance Sheet'!F18>0,'Profit & Loss'!F4/'Balance Sheet'!F18,0) -> 13.139983 | G21: =IF('Balance Sheet'!G18>0,'Profit & Loss'!G4/'Balance Sheet'!G18,0) -> 12.804199 | H21: =IF('Balance Sheet'!H18>0,'Profit & Loss'!H4/'Balance Sheet'!H18,0) -> 14.250765 | I21: =IF('Balance Sheet'!I18>0,'Profit & Loss'!I4/'Balance Sheet'!I18,0) -> 15.389359 | ... K21: =IF('Balance Sheet'!K18>0,'Profit & Loss'!K4/'Balance Sheet'!K18,0) -> 13.461683
A23: Return on Equity | B23: =IF(SUM('Balance Sheet'!B4:B5)>0,'Profit & Loss'!B12/SUM('Balance Sheet'!B4:B5),"") -> 0.66370107 | C23: =IF(SUM('Balance Sheet'!C4:C5)>0,'Profit & Loss'!C12/SUM('Balance Sheet'!C4:C5),"") -> 0.71611042 | D23: =IF(SUM('Balance Sheet'!D4:D5)>0,'Profit & Loss'!D12/SUM('Balance Sheet'!D4:D5),"") -> 0.76954366 | E23: =IF(SUM('Balance Sheet'!E4:E5)>0,'Profit & Loss'!E12/SUM('Balance Sheet'!E4:E5),"") -> 0.82002673 | F23: =IF(SUM('Balance Sheet'!F4:F5)>0,'Profit & Loss'!F12/SUM('Balance Sheet'!F4:F5),"") -> 0.16770147 | G23: =IF(SUM('Balance Sheet'!G4:G5)>0,'Profit & Loss'!G12/SUM('Balance Sheet'!G4:G5),"") -> 0.18097878 | H23: =IF(SUM('Balance Sheet'!H4:H5)>0,'Profit & Loss'!H12/SUM('Balance Sheet'!H4:H5),"") -> 0.20117684 | I23: =IF(SUM('Balance Sheet'!I4:I5)>0,'Profit & Loss'!I12/SUM('Balance Sheet'!I4:I5),"") -> 0.20065211 | ... K23: =IF(SUM('Balance Sheet'!K4:K5)>0,'Profit & Loss'!K12/SUM('Balance Sheet'!K4:K5),"") -> 0.30858245
A24: Return on Capital Emp | C24: =IF((B4+B5+B6+C4+C5+C6)>0,('Profit & Loss'!C10+'Profit & Loss'!C9)*2/(B4+B5+B6+C4+C5+C6),"") -> 1.0253111 | D24: =IF((C4+C5+C6+D4+D5+D6)>0,('Profit & Loss'!D10+'Profit & Loss'!D9)*2/(C4+C5+C6+D4+D5+D6),"") -> 1.1329442 | E24: =IF((D4+D5+D6+E4+E5+E6)>0,('Profit & Loss'!E10+'Profit & Loss'!E9)*2/(D4+D5+D6+E4+E5+E6),"") -> 1.1464032 | F24: =IF((E4+E5+E6+F4+F5+F6)>0,('Profit & Loss'!F10+'Profit & Loss'!F9)*2/(E4+E5+E6+F4+F5+F6),"") -> 0.38359301 | G24: =IF((F4+F5+F6+G4+G5+G6)>0,('Profit & Loss'!G10+'Profit & Loss'!G9)*2/(F4+F5+F6+G4+G5+G6),"") -> 0.24514717 | H24: =IF((G4+G5+G6+H4+H5+H6)>0,('Profit & Loss'!H10+'Profit & Loss'!H9)*2/(G4+G5+G6+H4+H5+H6),"") -> 0.26485088 | I24: =IF((H4+H5+H6+I4+I5+I6)>0,('Profit & Loss'!I10+'Profit & Loss'!I9)*2/(H4+H5+H6+I4+I5+I6),"") -> 0.27363876 | J24: =IF((I4+I5+I6+J4+J5+J6)>0,('Profit & Loss'!J10+'Profit & Loss'!J9)*2/(I4+I5+I6+J4+J5+J6),"") -> 0.28548847 | K24: =IF((J4+J5+J6+K4+K5+K6)>0,('Profit & Loss'!K10+'Profit & Loss'!K9)*2/(J4+J5+J6+K4+K5+K6),"") -> 0.36791847

Sheet Cash Flow
A1: ='Balance Sheet'!A1 -> HINDUSTAN UNILEVER LTD | E1: =UPDATE | J1: SCREENER.IN
A3: Narration | B3: ='Data Sheet'!B81 -> 42825 | C3: ='Data Sheet'!C81 -> 43190 | D3: ='Data Sheet'!D81 -> 43555 | E3: ='Data Sheet'!E81 -> 43921 | F3: ='Data Sheet'!F81 -> 44286 | G3: ='Data Sheet'!G81 -> 44651 | H3: ='Data Sheet'!H81 -> 45016 | I3: ='Data Sheet'!I81 -> 45382 | ... K3: ='Data Sheet'!K81 -> 46112
A4: Cash from Operating Activity | B4: ='Data Sheet'!B82 -> 5185 | C4: ='Data Sheet'!C82 -> 6059 | D4: ='Data Sheet'!D82 -> 5800 | E4: ='Data Sheet'!E82 -> 7623 | F4: ='Data Sheet'!F82 -> 9163 | G4: ='Data Sheet'!G82 -> 9048 | H4: ='Data Sheet'!H82 -> 9991 | I4: ='Data Sheet'!I82 -> 15469 | ... K4: ='Data Sheet'!K82 -> 10999
A5: Cash from Investing Activity | B5: ='Data Sheet'!B83 -> -1173 | C5: ='Data Sheet'!C83 -> -1063 | D5: ='Data Sheet'!D83 -> -438 | E5: ='Data Sheet'!E83 -> 1791 | F5: ='Data Sheet'!F83 -> -1228 | G5: ='Data Sheet'!G83 -> -1728 | H5: ='Data Sheet'!H83 -> -1484 | I5: ='Data Sheet'!I83 -> -5324 | ... K5: ='Data Sheet'!K83 -> -3684
A6: Cash from Financing Activity | B6: ='Data Sheet'!B84 -> -4214 | C6: ='Data Sheet'!C84 -> -4975 | D6: ='Data Sheet'!D84 -> -5390 | E6: ='Data Sheet'!E84 -> -6819 | F6: ='Data Sheet'!F84 -> -9309 | G6: ='Data Sheet'!G84 -> -8015 | H6: ='Data Sheet'!H84 -> -8953 | I6: ='Data Sheet'!I84 -> -10034 | ... K6: ='Data Sheet'!K84 -> -10810
A7: Net Cash Flow | B7: ='Data Sheet'!B85 -> -202 | C7: ='Data Sheet'!C85 -> 21 | D7: ='Data Sheet'!D85 -> -28 | E7: ='Data Sheet'!E85 -> 2595 | F7: ='Data Sheet'!F85 -> -1374 | G7: ='Data Sheet'!G85 -> -695 | H7: ='Data Sheet'!H85 -> -446 | I7: ='Data Sheet'!I85 -> 111 | ... K7: ='Data Sheet'!K85 -> -3495

Sheet Customization
A1: How to use it?
A3: You can customize this workbook as you want.
B4: You can add custom formating, add conditional formating, add your own formulas… do ANYTHING.
B5: Please don't edit the "Data Sheet" only.
A7: After customization, you can upload this back on Screener.
B8: Upload on: | C8: https://www.screener.in/excel/
A10: Download your customized workbooks now onwards.
B11: Now whenever you will "Export to excel" from Screener, it will export your customized file.
A14: TESTING:
B15: This is a testing feature currently.
B16: You can report any formula errors on the worksheet at: support@screener.in

Sheet Data Sheet
A1: COMPANY NAME | B1: HINDUSTAN UNILEVER LTD | E1: =IF(B2<>B3,"A NEW VERSION OF THE WORKSHEET IS AVAILABLE","")
A2: LATEST VERSION | B2: 2.1 | E2: PLEASE DO NOT MAKE ANY CHANGES TO THIS SHEET
A3: CURRENT VERSION | B3: 2.1
A5: META
A6: Number of shares | B6: =IF(B9>0,B9/B8,0) -> 234.95913
A7: Face Value | B7: 1
A8: Current Price | B8: 2272.2
A9: Market Capitalization | B9: 533874.13
A15: PROFIT & LOSS
A16: Report Date | B16: 42825 | C16: 43190 | D16: 43555 | E16: 43921 | F16: 44286 | G16: 44651 | H16: 45016 | I16: 45382 | J16: 45747 | K16: 46112
A17: Sales | B17: 33162 | C17: 35545 | D17: 39310 | E17: 39783 | F17: 47028 | G17: 52446 | H17: 60580 | I17: 61896 | J17: 63121 | K17: 64468
A18: Raw Material Cost | B18: 13606 | C18: 14233 | D18: 15845 | E18: 15697 | F18: 20141 | G18: 22871 | H18: 28427 | I18: 26822 | J18: 27344 | K18: 32094
A19: Change in Inventory | B19: -144 | C19: 72 | D19: -12 | E19: 108 | F19: 405 | G19: 22 | H19: 75 | I19: 11 | J19: 153 | K19: 429
A20: Power and Fuel | B20: 295 | C20: 295 | D20: 308 | E20: 299 | F20: 339 | G20: 318 | H20: 384 | I20: 446 | J20: 427
A21: Other Mfr. Exp | B21: 2887 | C21: 2998 | D21: 3041 | E21: 2906 | F21: 2868 | G21: 3354 | H21: 3791 | I21: 3385 | J21: 3834
A22: Employee Cost | B22: 1743 | C22: 1860 | D22: 1875 | E22: 1820 | F22: 2358 | G22: 2545 | H22: 2854 | I22: 3009 | J22: 3077 | K22: 3175
A23: Selling and admin | B23: 6689 | C23: 7252 | D23: 7796 | E23: 7620 | F23: 7906 | G23: 8164 | H23: 8785 | I23: 10780 | J23: 10693 | K23: 6261
A24: Other Expenses | B24: 1470 | C24: 1480 | D24: 1553 | E24: 1688 | F24: 2195 | G24: 2359 | H24: 2267 | I24: 2806 | J24: 3056 | K24: 8328
A25: Other Income | B25: 606 | C25: 353 | D25: 322 | E25: 424 | F25: 170 | G25: 219 | H25: 448 | I25: 817 | J25: 1322 | K25: 4923
A26: Depreciation | B26: 432 | C26: 520 | D26: 565 | E26: 1002 | F26: 1074 | G26: 1091 | H26: 1137 | I26: 1216 | J26: 1355 | K26: 1333
A27: Interest | B27: 35 | C27: 26 | D27: 33 | E27: 118 | F27: 117 | G27: 106 | H27: 114 | I27: 334 | J27: 395 | K27: 410
A28: Profit before tax | B28: 6467 | C28: 7306 | D28: 8604 | E28: 9165 | F28: 10605 | G28: 11879 | H28: 13344 | I28: 13926 | J28: 14415 | K28: 18219
A29: Tax | B29: 1977 | C29: 2079 | D29: 2544 | E29: 2409 | F29: 2606 | G29: 2987 | H29: 3201 | I29: 3644 | J29: 3744 | K29: 3160
A30: Net profit | B30: 4476 | C30: 5214 | D30: 6054 | E30: 6748 | F30: 7995 | G30: 8879 | H30: 10120 | I30: 10277 | J30: 10649 | K30: 15040
A31: Dividend Amount | B31: 3672 | C31: 4320 | D31: 4752 | E31: 5400 | F31: 9517.5 | G31: 7990 | H31: 9165 | I31: 9870 | J31: 12455 | K31: 9635
A40: Quarters
A41: Report Date | B41: 45291 | C41: 45382 | D41: 45473 | E41: 45565 | F41: 45657 | G41: 45747 | H41: 45838 | I41: 45930 | J41: 46022 | K41: 46112
A42: Sales | B42: 15567 | C42: 15210 | D42: 15707 | E42: 15926 | F42: 15556 | G42: 15190 | H42: 16514 | I42: 15919 | J42: 16441 | K42: 16351
A43: Expenses | B43: 11902 | C43: 11675 | D43: 11965 | E43: 12139 | F43: 11867 | G43: 11572 | H43: 12797 | I43: 12137 | J43: 12660 | K43: 12514
A44: Other Income | B44: 184 | C44: 309 | D44: 209 | E44: 203 | F44: 733 | G44: 149 | H44: 74 | I44: 269 | J44: 4048 | K44: 503
A45: Depreciation | B45: 313 | C45: 320 | D45: 329 | E45: 338 | F45: 318 | G45: 318 | H45: 361 | I45: 322 | J45: 337 | K45: 348
A46: Interest | B46: 91 | C46: 105 | D46: 93 | E46: 110 | F46: 109 | G46: 77 | H46: 127 | I46: 124 | J46: 88 | K46: 76
A47: Profit before tax | B47: 3445 | C47: 3419 | D47: 3529 | E47: 3542 | F47: 3995 | G47: 3372 | H47: 3303 | I47: 3605 | J47: 7404 | K47: 3916
A48: Tax | B48: 937 | C48: 858 | D48: 917 | E48: 947 | F48: 1006 | G48: 897 | H48: 535 | I48: 911 | J48: 801 | K48: 922
A49: Net profit | B49: 2509 | C49: 2558 | D49: 2610 | E49: 2591 | F49: 2984 | G49: 2464 | H49: 2756 | I49: 2685 | J49: 6607 | K49: 2992
A50: Operating Profit | B50: 3665 | C50: 3535 | D50: 3742 | E50: 3787 | F50: 3689 | G50: 3618 | H50: 3717 | I50: 3782 | J50: 3781 | K50: 3837
A55: BALANCE SHEET
A56: Report Date | B56: 42825 | C56: 43190 | D56: 43555 | E56: 43921 | F56: 44286 | G56: 44651 | H56: 45016 | I56: 45382 | J56: 45747 | K56: 46112
A57: Equity Share Capital | B57: 216 | C57: 216 | D57: 216 | E57: 216 | F57: 235 | G57: 235 | H57: 235 | I57: 235 | J57: 235 | K57: 235
A58: Reserves | B58: 6528 | C58: 7065 | D58: 7651 | E58: 8013 | F58: 47439 | G58: 48826 | H58: 50069 | I58: 50983 | J58: 49167 | K58: 48504
...
